Traceback (most recent call last):
  File "/usr/local/lib/python3.10/dist-packages/jupyter_cache/executors/utils.py", line 58, in single_nb_execution
    executenb(
  File "/usr/local/lib/python3.10/dist-packages/nbclient/client.py", line 1319, in execute
    return NotebookClient(nb=nb, resources=resources, km=km, **kwargs).execute()
  File "/home/pedromartineli/.local/lib/python3.10/site-packages/jupyter_core/utils/__init__.py", line 165, in wrapped
    return loop.run_until_complete(inner)
  File "/usr/lib/python3.10/asyncio/base_events.py", line 649, in run_until_complete
    return future.result()
  File "/usr/local/lib/python3.10/dist-packages/nbclient/client.py", line 709, in async_execute
    await self.async_execute_cell(
  File "/usr/local/lib/python3.10/dist-packages/nbclient/client.py", line 1062, in async_execute_cell
    await self._check_raise_for_error(cell, cell_index, exec_reply)
  File "/usr/local/lib/python3.10/dist-packages/nbclient/client.py", line 918, in _check_raise_for_error
    raise CellExecutionError.from_cell_and_msg(cell, exec_reply_content)
nbclient.exceptions.CellExecutionError: An error occurred while executing the following cell:
------------------
from vega_datasets import data  # importa vega_datasets
cars = data.cars()              # carrega os dados de carros como um data frame do Pandas
cars.head()                     # mostra as primeiras cinco linhas
------------------


[0;31m---------------------------------------------------------------------------[0m
[0;31mModuleNotFoundError[0m                       Traceback (most recent call last)
Cell [0;32mIn[2], line 1[0m
[0;32m----> 1[0m [38;5;28;01mfrom[39;00m[38;5;250m [39m[38;5;21;01mvega_datasets[39;00m[38;5;250m [39m[38;5;28;01mimport[39;00m data  [38;5;66;03m# importa vega_datasets[39;00m
[1;32m      2[0m cars [38;5;241m=[39m data[38;5;241m.[39mcars()              [38;5;66;03m# carrega os dados de carros como um data frame do Pandas[39;00m
[1;32m      3[0m cars[38;5;241m.[39mhead()                     [38;5;66;03m# mostra as primeiras cinco linhas[39;00m

[0;31mModuleNotFoundError[0m: No module named 'vega_datasets'

