Traceback (most recent call last):
  File "/usr/local/lib/python3.10/dist-packages/jupyter_cache/executors/utils.py", line 58, in single_nb_execution
    executenb(
  File "/usr/local/lib/python3.10/dist-packages/nbclient/client.py", line 1319, in execute
    return NotebookClient(nb=nb, resources=resources, km=km, **kwargs).execute()
  File "/home/pedromartineli/.local/lib/python3.10/site-packages/jupyter_core/utils/__init__.py", line 165, in wrapped
    return loop.run_until_complete(inner)
  File "/usr/lib/python3.10/asyncio/base_events.py", line 649, in run_until_complete
    return future.result()
  File "/usr/local/lib/python3.10/dist-packages/nbclient/client.py", line 709, in async_execute
    await self.async_execute_cell(
  File "/usr/local/lib/python3.10/dist-packages/nbclient/client.py", line 1062, in async_execute_cell
    await self._check_raise_for_error(cell, cell_index, exec_reply)
  File "/usr/local/lib/python3.10/dist-packages/nbclient/client.py", line 918, in _check_raise_for_error
    raise CellExecutionError.from_cell_and_msg(cell, exec_reply_content)
nbclient.exceptions.CellExecutionError: An error occurred while executing the following cell:
------------------
conda install -c conda-forge altair vega_datasets
------------------


[0;31m---------------------------------------------------------------------------[0m
[0;31mValueError[0m                                Traceback (most recent call last)
Cell [0;32mIn[2], line 1[0m
[0;32m----> 1[0m [43mget_ipython[49m[43m([49m[43m)[49m[38;5;241;43m.[39;49m[43mrun_line_magic[49m[43m([49m[38;5;124;43m'[39;49m[38;5;124;43mconda[39;49m[38;5;124;43m'[39;49m[43m,[49m[43m [49m[38;5;124;43m'[39;49m[38;5;124;43minstall -c conda-forge altair vega_datasets[39;49m[38;5;124;43m'[39;49m[43m)[49m

File [0;32m~/.local/lib/python3.10/site-packages/IPython/core/interactiveshell.py:2482[0m, in [0;36mInteractiveShell.run_line_magic[0;34m(self, magic_name, line, _stack_depth)[0m
[1;32m   2480[0m     kwargs[[38;5;124m'[39m[38;5;124mlocal_ns[39m[38;5;124m'[39m] [38;5;241m=[39m [38;5;28mself[39m[38;5;241m.[39mget_local_scope(stack_depth)
[1;32m   2481[0m [38;5;28;01mwith[39;00m [38;5;28mself[39m[38;5;241m.[39mbuiltin_trap:
[0;32m-> 2482[0m     result [38;5;241m=[39m [43mfn[49m[43m([49m[38;5;241;43m*[39;49m[43margs[49m[43m,[49m[43m [49m[38;5;241;43m*[39;49m[38;5;241;43m*[39;49m[43mkwargs[49m[43m)[49m
[1;32m   2484[0m [38;5;66;03m# The code below prevents the output from being displayed[39;00m
[1;32m   2485[0m [38;5;66;03m# when using magics with decorator @output_can_be_silenced[39;00m
[1;32m   2486[0m [38;5;66;03m# when the last Python token in the expression is a ';'.[39;00m
[1;32m   2487[0m [38;5;28;01mif[39;00m [38;5;28mgetattr[39m(fn, magic[38;5;241m.[39mMAGIC_OUTPUT_CAN_BE_SILENCED, [38;5;28;01mFalse[39;00m):

File [0;32m~/.local/lib/python3.10/site-packages/IPython/core/magics/packaging.py:27[0m, in [0;36mis_conda_environment.<locals>.wrapper[0;34m(*args, **kwargs)[0m
[1;32m     25[0m [38;5;66;03m# TODO: does this need to change on windows?[39;00m
[1;32m     26[0m [38;5;28;01mif[39;00m [38;5;129;01mnot[39;00m Path(sys[38;5;241m.[39mprefix, [38;5;124m"[39m[38;5;124mconda-meta[39m[38;5;124m"[39m, [38;5;124m"[39m[38;5;124mhistory[39m[38;5;124m"[39m)[38;5;241m.[39mexists():
[0;32m---> 27[0m     [38;5;28;01mraise[39;00m [38;5;167;01mValueError[39;00m(
[1;32m     28[0m         [38;5;124m"[39m[38;5;124mThe python kernel does not appear to be a conda environment.  [39m[38;5;124m"[39m
[1;32m     29[0m         [38;5;124m"[39m[38;5;124mPlease use ``[39m[38;5;124m%[39m[38;5;124mpip install`` instead.[39m[38;5;124m"[39m
[1;32m     30[0m     )
[1;32m     31[0m [38;5;28;01mreturn[39;00m func([38;5;241m*[39margs, [38;5;241m*[39m[38;5;241m*[39mkwargs)

[0;31mValueError[0m: The python kernel does not appear to be a conda environment.  Please use ``%pip install`` instead.

